<?xml version="1.0" ?>
<robot name="URDF" xmlns:xacro="http://www.ros.org/wiki/xacro">

<xacro:include filename="$(find rover)/rover/simulation/urdfs/Arm_CIRC_2024/materials.xacro" />
<!-- <xacro:include filename="$(find URDF_description)/urdf/URDF.trans" />
<xacro:include filename="$(find URDF_description)/urdf/URDF.gazebo" /> -->
<link name="base_link">
  <inertial>
    <origin xyz="0.049999999999908465 0.03732491617294113 0.003125" rpy="0 0 0"/>
    <mass value="0.3438852516301944"/>
    <inertia ixx="0.000173" iyy="0.000307" izz="0.000477" ixy="0.0" iyz="0.0" ixz="0.0"/>
  </inertial>
  <visual>
    <origin xyz="0 0 0" rpy="0 0 0"/>
    <geometry>
      <mesh filename="package://rover/rover/simulation/meshes/Arm_CIRC_2024/base_link.stl" scale="0.001 0.001 0.001"/>
    </geometry>
    <material name="silver"/>
  </visual>
  <collision>
    <origin xyz="0 0 0" rpy="0 0 0"/>
    <geometry>
      <mesh filename="package://rover/rover/simulation/meshes/Arm_CIRC_2024/base_link.stl" scale="0.001 0.001 0.001"/>
    </geometry>
  </collision>
</link>

<!-- Target Position Arm -->

<link name="link_2">
  <inertial>
    <origin xyz="0.025 -3.469446951953614e-17 0.18000000000000033" rpy="0 0 0"/>
    <mass value="1.8376728470103898"/>
    <inertia ixx="0.025547" iyy="0.025522" izz="0.001359" ixy="-0.0" iyz="0.0" ixz="0.0"/>
  </inertial>
  <visual>
    <origin xyz="-0.025 -0.043125 -0.10125" rpy="0 0 0"/>
    <geometry>
      <mesh filename="package://rover/rover/simulation/meshes/Arm_CIRC_2024/link_2_1.stl" scale="0.001 0.001 0.001"/>
    </geometry>
    <material name="silver"/>
  </visual>
  <collision>
    <origin xyz="-0.025 -0.043125 -0.10125" rpy="0 0 0"/>
    <geometry>
      <mesh filename="package://rover/rover/simulation/meshes/Arm_CIRC_2024/link_2_1.stl" scale="0.001 0.001 0.001"/>
    </geometry>
  </collision>
</link>

<link name="link_3">
  <inertial>
    <origin xyz="0.03437499999999987 -0.06837766852843247 0.012917814574353537" rpy="0 0 0"/>
    <mass value="0.5703271438853911"/>
    <inertia ixx="0.001379" iyy="0.000828" izz="0.001699" ixy="0.0" iyz="0.000233" ixz="0.0"/>
  </inertial>
  <visual>
    <origin xyz="-0.025 -0.043125 -0.46125" rpy="0 0 0"/>
    <geometry>
      <mesh filename="package://rover/rover/simulation/meshes/Arm_CIRC_2024/link_3_1.stl" scale="0.001 0.001 0.001"/>
    </geometry>
    <material name="silver"/>
  </visual>
  <collision>
    <origin xyz="-0.025 -0.043125 -0.46125" rpy="0 0 0"/>
    <geometry>
      <mesh filename="package://rover/rover/simulation/meshes/Arm_CIRC_2024/link_3_1.stl" scale="0.001 0.001 0.001"/>
    </geometry>
  </collision>
</link>

<link name="link_4">
  <inertial>
    <origin xyz="-5.140400912143073e-05 1.5265566588595902e-16 0.14186043457020492" rpy="0 0 0"/>
    <mass value="1.4205958730202999"/>
    <inertia ixx="0.012764" iyy="0.012172" izz="0.001822" ixy="0.0" iyz="0.0" ixz="-6e-06"/>
  </inertial>
  <visual>
    <origin xyz="-0.059375 0.056875 -0.50625" rpy="0 0 0"/>
    <geometry>
      <mesh filename="package://rover/rover/simulation/meshes/Arm_CIRC_2024/link_4_1.stl" scale="0.001 0.001 0.001"/>
    </geometry>
    <material name="silver"/>
  </visual>
  <collision>
    <origin xyz="-0.059375 0.056875 -0.50625" rpy="0 0 0"/>
    <geometry>
      <mesh filename="package://rover/rover/simulation/meshes/Arm_CIRC_2024/link_4_1.stl" scale="0.001 0.001 0.001"/>
    </geometry>
  </collision>
</link>

<link name="link_5">
  <inertial>
    <origin xyz="-0.024457508265359702 0.06037500000000042 -0.00023164099942307725" rpy="0 0 0"/>
    <mass value="1.03093485941646"/>
    <inertia ixx="0.000373" iyy="0.001033" izz="0.001033" ixy="-0.0" iyz="0.0" ixz="-8e-06"/>
  </inertial>
  <visual>
    <origin xyz="-0.0667 0.11725 -0.80125" rpy="0 0 0"/>
    <geometry>
      <mesh filename="package://rover/rover/simulation/meshes/Arm_CIRC_2024/link_5_1.stl" scale="0.001 0.001 0.001"/>
    </geometry>
    <material name="silver"/>
  </visual>
  <collision>
    <origin xyz="-0.0667 0.11725 -0.80125" rpy="0 0 0"/>
    <geometry>
      <mesh filename="package://rover/rover/simulation/meshes/Arm_CIRC_2024/link_5_1.stl" scale="0.001 0.001 0.001"/>
    </geometry>
  </collision>
</link>

<link name="link_1">
  <inertial>
    <origin xyz="-7.179673522372809e-14 -0.00017173384764001404 0.04577852526730277" rpy="0 0 0"/>
    <mass value="0.4382416946666404"/>
    <inertia ixx="0.000842" iyy="0.000973" izz="0.000383" ixy="0.0" iyz="4e-06" ixz="-0.0"/>
  </inertial>
  <visual>
    <origin xyz="-0.05 -0.04 -0.00625" rpy="0 0 0"/>
    <geometry>
      <mesh filename="package://rover/rover/simulation/meshes/Arm_CIRC_2024/link_1_1.stl" scale="0.001 0.001 0.001"/>
    </geometry>
    <material name="silver"/>
  </visual>
  <collision>
    <origin xyz="-0.05 -0.04 -0.00625" rpy="0 0 0"/>
    <geometry>
      <mesh filename="package://rover/rover/simulation/meshes/Arm_CIRC_2024/link_1_1.stl" scale="0.001 0.001 0.001"/>
    </geometry>
  </collision>
</link>

<link name="link_6">
  <inertial>
    <origin xyz="0.0010598645437465554 -0.0008893319477553327 0.0349620310530927" rpy="0 0 0"/>
    <mass value="2.291208404674366"/>
    <inertia ixx="0.002485" iyy="0.002561" izz="0.003312" ixy="0.000217" iyz="5.2e-05" ixz="-6.2e-05"/>
  </inertial>
  <visual>
    <origin xyz="-0.059375 0.056875 -0.82625" rpy="0 0 0"/>
    <geometry>
      <mesh filename="package://rover/rover/simulation/meshes/Arm_CIRC_2024/link_6_1.stl" scale="0.001 0.001 0.001"/>
    </geometry>
    <material name="silver"/>
  </visual>
  <collision>
    <origin xyz="-0.059375 0.056875 -0.82625" rpy="0 0 0"/>
    <geometry>
      <mesh filename="package://rover/rover/simulation/meshes/Arm_CIRC_2024/link_6_1.stl" scale="0.001 0.001 0.001"/>
    </geometry>
  </collision>
</link>

<link name="link_7">
  <inertial>
    <origin xyz="-0.0017868967775850429 -0.0050280961807210095 0.046368119669020325" rpy="0 0 0"/>
    <mass value="0.07042769953386392"/>
    <inertia ixx="9.8e-05" iyy="9.8e-05" izz="1e-06" ixy="0.0" iyz="3e-06" ixz="-4e-06"/>
  </inertial>
  <visual>
    <origin xyz="0.007887 -0.006092 -0.89025" rpy="0 0 0"/>
    <geometry>
      <mesh filename="package://rover/rover/simulation/meshes/Arm_CIRC_2024/link_7_1.stl" scale="0.001 0.001 0.001"/>
    </geometry>
    <material name="silver"/>
  </visual>
  <collision>
    <origin xyz="0.007887 -0.006092 -0.89025" rpy="0 0 0"/>
    <geometry>
      <mesh filename="package://rover/rover/simulation/meshes/Arm_CIRC_2024/link_7_1.stl" scale="0.001 0.001 0.001"/>
    </geometry>
  </collision>
</link>

<link name="link_8">
  <inertial>
    <origin xyz="-0.01999999999995168 4.163336342344337e-16 0.0008309682104638005" rpy="0 0 0"/>
    <mass value="0.5216667986958432"/>
    <inertia ixx="0.000144" iyy="0.000144" izz="0.000135" ixy="0.0" iyz="0.0" ixz="-0.0"/>
  </inertial>
  <visual>
    <origin xyz="0.015625 0.056875 -0.800574" rpy="0 0 0"/>
    <geometry>
      <mesh filename="package://rover/rover/simulation/meshes/Arm_CIRC_2024/link_8_1.stl" scale="0.001 0.001 0.001"/>
    </geometry>
    <material name="silver"/>
  </visual>
  <collision>
    <origin xyz="0.015625 0.056875 -0.800574" rpy="0 0 0"/>
    <geometry>
      <mesh filename="package://rover/rover/simulation/meshes/Arm_CIRC_2024/link_8_1.stl" scale="0.001 0.001 0.001"/>
    </geometry>
  </collision>
</link>

<link name="link_9">
  <inertial>
    <origin xyz="-0.002703449377635364 0.004600114186135838 0.04636811966902077" rpy="0 0 0"/>
    <mass value="0.07042769953386384"/>
    <inertia ixx="9.8e-05" iyy="9.8e-05" izz="1e-06" ixy="-0.0" iyz="1e-06" ixz="5e-06"/>
  </inertial>
  <visual>
    <origin xyz="-0.150846 0.045823 -0.89025" rpy="0 0 0"/>
    <geometry>
      <mesh filename="package://rover/rover/simulation/meshes/Arm_CIRC_2024/link_9_1.stl" scale="0.001 0.001 0.001"/>
    </geometry>
    <material name="silver"/>
  </visual>
  <collision>
    <origin xyz="-0.150846 0.045823 -0.89025" rpy="0 0 0"/>
    <geometry>
      <mesh filename="package://rover/rover/simulation/meshes/Arm_CIRC_2024/link_9_1.stl" scale="0.001 0.001 0.001"/>
    </geometry>
  </collision>
</link>

<link name="camera_link">
  <inertial>
    <origin xyz="0.005000000000008033 0.0018630668261348793 0.04636811966902077" rpy="0 0 0"/>
    <mass value="0.07042769953386384"/>
    <inertia ixx="9.8e-05" iyy="9.8e-05" izz="1e-06" ixy="-0.0" iyz="-5e-06" ixz="0.0"/>
  </inertial>
  <visual>
    <origin xyz="-0.054375 0.148875 -0.89025" rpy="0 0 0"/>
    <geometry>
      <mesh filename="package://rover/rover/simulation/meshes/Arm_CIRC_2024/camera_link_1.stl" scale="0.001 0.001 0.001"/>
    </geometry>
    <material name="silver"/>
  </visual>
  <collision>
    <origin xyz="-0.054375 0.148875 -0.89025" rpy="0 0 0"/>
    <geometry>
      <mesh filename="package://rover/rover/simulation/meshes/Arm_CIRC_2024/camera_link_1.stl" scale="0.001 0.001 0.001"/>
    </geometry>
  </collision>
</link>

<joint name="Joint_1" type="continuous">
  <origin xyz="0.05 0.04 0.00625" rpy="0 0 0"/>
  <parent link="base_link"/>
  <child link="link_1"/>
  <axis xyz="0.0 0.0 1.0"/>
</joint>

<joint name="Joint_2" type="continuous">
  <origin xyz="-0.025 0.003125 0.095" rpy="0 0 0"/>
  <parent link="link_1"/>
  <child link="link_2"/>
  <axis xyz="1.0 0.0 -0.0"/>
</joint>

<joint name="Joint_3" type="continuous">
  <origin xyz="0.0 0.0 0.36" rpy="-1.57 0 0"/>
  <parent link="link_2"/>
  <child link="link_3"/>
  <axis xyz="-1.0 -0.0 0.0"/>
</joint>

<joint name="Joint_4" type="continuous">
  <origin xyz="0.034375 -0.1 0.045" rpy="0 0 1.57"/>
  <parent link="link_3"/>
  <child link="link_4"/>
  <axis xyz="0.0 0.0 1.0"/>
</joint>

<joint name="Joint_5" type="continuous">
  <origin xyz="0.007325 -0.060375 0.295" rpy="0 0 0"/>
  <parent link="link_4"/>
  <child link="link_5"/>
  <axis xyz="-0.0 -1.0 -0.0"/>
</joint>

<joint name="Joint_6" type="continuous">
  <origin xyz="-0.007325 0.060375 0.025" rpy="0 0 0"/>
  <parent link="link_5"/>
  <child link="link_6"/>
  <axis xyz="-0.0 0.0 -1.0"/>
</joint>

<joint name="Joint_7" type="fixed">
  <origin xyz="-0.067262 0.062967 0.064" rpy="0 0 0"/>
  <parent link="link_6"/>
  <child link="link_7"/>
  <axis xyz="0.642788 0.766044 0.0"/>
</joint>

<joint name="Camera_Joint" type="fixed">
  <origin xyz="-0.082325 0.060375 -0.000676" rpy="0 0 0"/>
  <parent link="link_5"/>
  <child link="link_8"/>
</joint>

<joint name="Joint_8" type="fixed">
  <origin xyz="0.091471 0.011052 0.064" rpy="0 0 0"/>
  <parent link="link_6"/>
  <child link="link_9"/>
  <axis xyz="0.173648 -0.984808 -0.0"/>
</joint>

<joint name="Joint_9" type="fixed">
  <origin xyz="-0.005 -0.092 0.064" rpy="0 0 0"/>
  <parent link="link_6"/>
  <child link="camera_link"/>
  <axis xyz="-1.0 0.0 0.0"/>
</joint>

</robot>
