<?xml version="1.0" encoding="utf-8"?>
<!-- This URDF was automatically created by SolidWorks to URDF Exporter! Originally created by Stephen Brawner (brawner@gmail.com) 
     Commit Version: 1.6.0-4-g7f85cfe  Build Version: 1.6.7995.38578
     For more information, please see http://wiki.ros.org/sw_urdf_exporter -->
<robot
  name="rover">
  <link
    name="chassis">
    <inertial>
      <origin
        xyz="0.2806 0.39193 0.4973"
        rpy="0 0 0" />
      <mass
        value="1.2964" />
      <inertia
        ixx="0.0067285"
        ixy="1.6749E-11"
        ixz="4.187E-12"
        iyy="0.014129"
        iyz="4.2311E-11"
        izz="0.020236" />
    </inertial>
    <visual>
      <origin
        xyz="0 0 0"
        rpy="0 0 0" />
      <geometry>
        <mesh
          filename="package://rover/meshes/chassis.STL" />
      </geometry>
      <material
        name="">
        <color
          rgba="0.75294 0.75294 0.75294 1" />
      </material>
    </visual>
    <collision>
      <origin
        xyz="0 0 0"
        rpy="0 0 0" />
      <geometry>
        <mesh
          filename="package://rover/meshes/chassis.STL" />
      </geometry>
    </collision>
  </link>
  <link
    name="rocker_1">
    <inertial>
      <origin
        xyz="-0.06340165227202 0.0349398172882702 0.170844109095454"
        rpy="0 0 0" />
      <mass
        value="0.70205795902915" />
      <inertia
        ixx="0.00217365418533618"
        ixy="6.72961454379896E-19"
        ixz="-0.00213217567457792"
        iyy="0.00810448763367225"
        iyz="9.82127545938036E-19"
        izz="0.00630951857064517" />
    </inertial>
    <visual>
      <origin
        xyz="0 0 0"
        rpy="0 0 0" />
      <geometry>
        <mesh
          filename="package://rover/meshes/rocker_1.STL" />
      </geometry>
      <material
        name="">
        <color
          rgba="0.752941176470588 0.752941176470588 0.752941176470588 1" />
      </material>
    </visual>
    <collision>
      <origin
        xyz="0 0 0"
        rpy="0 0 0" />
      <geometry>
        <mesh
          filename="package://rover/meshes/rocker_1.STL" />
      </geometry>
    </collision>
  </link>
  <joint
    name="joint_1"
    type="continuous">
    <origin
      xyz="0.257280649253525 0.686809397997044 0.442407585082231"
      rpy="3.14159265358979 0 0" />
    <parent
      link="chassis" />
    <child
      link="rocker_1" />
    <axis
      xyz="0 1 0" />
  </joint>
  <link
    name="wheel_1">
    <inertial>
      <origin
        xyz="-0.000176268264627466 -0.0635452754722254 -0.000101180829690989"
        rpy="0 0 0" />
      <mass
        value="3.71098878292473" />
      <inertia
        ixx="0.0272042721495548"
        ixy="4.78292852960967E-05"
        ixz="-4.80095002474376E-05"
        iyy="0.0486688742533957"
        iyz="2.76468584133017E-05"
        izz="0.0272554582914966" />
    </inertial>
    <visual>
      <origin
        xyz="0 0 0"
        rpy="0 0 0" />
      <geometry>
        <mesh
          filename="package://rover/meshes/wheel_1.STL" />
      </geometry>
      <material
        name="">
        <color
          rgba="0.752941176470588 0.752941176470588 0.752941176470588 1" />
      </material>
    </visual>
    <collision>
      <origin
        xyz="0 0 0"
        rpy="0 0 0" />
      <geometry>
        <mesh
          filename="package://rover/meshes/wheel_1.STL" />
      </geometry>
    </collision>
  </link>
  <joint
    name="joint_3"
    type="continuous">
    <origin
      xyz="0.56495774388434 0.714395200000001 0.343590017662668"
      rpy="0 0 0" />
    <parent
      link="rocker_1" />
    <child
      link="wheel_1" />
    <axis
      xyz="0 1 0" />
  </joint>
  <link
    name="wheel_2">
    <inertial>
      <origin
        xyz="0.000178620256588879 -0.0635452760057445 -9.69747168301782E-05"
        rpy="0 0 0" />
      <mass
        value="3.71098882720173" />
      <inertia
        ixx="0.0271986135723213"
        ixy="-4.86694249221818E-05"
        ixz="4.44328246276884E-05"
        iyy="0.0486688706200681"
        iyz="2.62407892387355E-05"
        izz="0.0272611104617968" />
    </inertial>
    <visual>
      <origin
        xyz="0 0 0"
        rpy="0 0 0" />
      <geometry>
        <mesh
          filename="package://rover/meshes/wheel_2.STL" />
      </geometry>
      <material
        name="">
        <color
          rgba="0.752941176470588 0.752941176470588 0.752941176470588 1" />
      </material>
    </visual>
    <collision>
      <origin
        xyz="0 0 0"
        rpy="0 0 0" />
      <geometry>
        <mesh
          filename="package://rover/meshes/wheel_2.STL" />
      </geometry>
    </collision>
  </link>
  <joint
    name="joint_4"
    type="continuous">
    <origin
      xyz="-0.570472245168088 0.7143947 0.337834102553307"
      rpy="0 0 0" />
    <parent
      link="rocker_1" />
    <child
      link="wheel_2" />
    <axis
      xyz="0 1 0" />
  </joint>
  <link
    name="wheel_3">
    <inertial>
      <origin
        xyz="0.00194962016213629 -0.0675452751530038 0.00121412273178784"
        rpy="0 0 0" />
      <mass
        value="3.71098876925042" />
      <inertia
        ixx="0.027207070366712"
        ixy="4.70156922204123E-05"
        ixz="-4.93994988582925E-05"
        iyy="0.0486688742508458"
        iyz="2.90088130203484E-05"
        izz="0.0272526600970484" />
    </inertial>
    <visual>
      <origin
        xyz="0 0 0"
        rpy="0 0 0" />
      <geometry>
        <mesh
          filename="package://rover/meshes/wheel_3.STL" />
      </geometry>
      <material
        name="">
        <color
          rgba="0.752941176470588 0.752941176470588 0.752941176470588 1" />
      </material>
    </visual>
    <collision>
      <origin
        xyz="0 0 0"
        rpy="0 0 0" />
      <geometry>
        <mesh
          filename="package://rover/meshes/wheel_3.STL" />
      </geometry>
    </collision>
  </link>
  <joint
    name="joint_5"
    type="continuous">
    <origin
      xyz="0.00283967293050863 0.718394699999995 0.348240293269966"
      rpy="0 0 0" />
    <parent
      link="rocker_1" />
    <child
      link="wheel_3" />
    <axis
      xyz="0 1 0" />
  </joint>
  <link
    name="rocker_2">
    <inertial>
      <origin
        xyz="-0.0569379504262083 -0.0279401827117303 0.173105600500696"
        rpy="0 0 0" />
      <mass
        value="0.702057959029176" />
      <inertia
        ixx="0.00201938596176855"
        ixy="8.3732485455951E-19"
        ixz="-0.00197087340304265"
        iyy="0.00810448763367223"
        iyz="3.63483547118532E-19"
        izz="0.00646378679421278" />
    </inertial>
    <visual>
      <origin
        xyz="0 0 0"
        rpy="0 0 0" />
      <geometry>
        <mesh
          filename="package://rover/meshes/rocker_2.STL" />
      </geometry>
      <material
        name="">
        <color
          rgba="0.752941176470588 0.752941176470588 0.752941176470588 1" />
      </material>
    </visual>
    <collision>
      <origin
        xyz="0 0 0"
        rpy="0 0 0" />
      <geometry>
        <mesh
          filename="package://rover/meshes/rocker_2.STL" />
      </geometry>
    </collision>
  </link>
  <joint
    name="joint_2"
    type="continuous">
    <origin
      xyz="0.256227202845866 0.104049397997044 0.442431681089809"
      rpy="3.14159265358979 0 0" />
    <parent
      link="chassis" />
    <child
      link="rocker_2" />
    <axis
      xyz="0 1 0" />
  </joint>
  <link
    name="wheel_4">
    <inertial>
      <origin
        xyz="0.0019402142500673 0.0675452760886098 0.00122909345359265"
        rpy="0 0 0" />
      <mass
        value="3.71098880339359" />
      <inertia
        ixx="0.0272054221801452"
        ixy="-4.65457353233808E-05"
        ixz="-4.86053275368699E-05"
        iyy="0.0486688742216412"
        iyz="-2.97572117954805E-05"
        izz="0.0272543080144616" />
    </inertial>
    <visual>
      <origin
        xyz="0 0 0"
        rpy="0 0 0" />
      <geometry>
        <mesh
          filename="package://rover/meshes/wheel_4.STL" />
      </geometry>
      <material
        name="">
        <color
          rgba="0.752941176470588 0.752941176470588 0.752941176470588 1" />
      </material>
    </visual>
    <collision>
      <origin
        xyz="0 0 0"
        rpy="0 0 0" />
      <geometry>
        <mesh
          filename="package://rover/meshes/wheel_4.STL" />
      </geometry>
    </collision>
  </link>
  <joint
    name="joint_6"
    type="continuous">
    <origin
      xyz="0.551575611997302 -0.711395200000009 0.36342985845553"
      rpy="0 0 0" />
    <parent
      link="rocker_2" />
    <child
      link="wheel_4" />
    <axis
      xyz="0 1 0" />
  </joint>
  <link
    name="wheel_5">
    <inertial>
      <origin
        xyz="0.0019041216458878 0.06754527636568 0.00128429872746434"
        rpy="0 0 0" />
      <mass
        value="3.71098879444043" />
      <inertia
        ixx="0.0272082525266688"
        ixy="-4.56720854207333E-05"
        ixz="-4.99283757989465E-05"
        iyy="0.0486688742007255"
        iyz="-3.10813719211118E-05"
        izz="0.0272514775789298" />
    </inertial>
    <visual>
      <origin
        xyz="0 0 0"
        rpy="0 0 0" />
      <geometry>
        <mesh
          filename="package://rover/meshes/wheel_5.STL" />
      </geometry>
      <material
        name="">
        <color
          rgba="0.752941176470588 0.752941176470588 0.752941176470588 1" />
      </material>
    </visual>
    <collision>
      <origin
        xyz="0 0 0"
        rpy="0 0 0" />
      <geometry>
        <mesh
          filename="package://rover/meshes/wheel_5.STL" />
      </geometry>
    </collision>
  </link>
  <joint
    name="joint_7"
    type="continuous">
    <origin
      xyz="-0.00821220849695886 -0.711395699999999 0.348294101803227"
      rpy="0 0 0" />
    <parent
      link="rocker_2" />
    <child
      link="wheel_5" />
    <axis
      xyz="0 1 0" />
  </joint>
  <link
    name="wheel_6">
    <inertial>
      <origin
        xyz="0.00018330802175881 0.0635452759428508 -8.77894037699112E-05"
        rpy="0 0 0" />
      <mass
        value="3.71098880842576" />
      <inertia
        ixx="0.0271974322179864"
        ixy="4.97534168565902E-05"
        ixz="4.36810350115338E-05"
        iyy="0.0486688742480146"
        iyz="-2.40124237929748E-05"
        izz="0.0272622980653803" />
    </inertial>
    <visual>
      <origin
        xyz="0 0 0"
        rpy="0 0 0" />
      <geometry>
        <mesh
          filename="package://rover/meshes/wheel_6.STL" />
      </geometry>
      <material
        name="">
        <color
          rgba="0.752941176470588 0.752941176470588 0.752941176470588 1" />
      </material>
    </visual>
    <collision>
      <origin
        xyz="0 0 0"
        rpy="0 0 0" />
      <geometry>
        <mesh
          filename="package://rover/meshes/wheel_6.STL" />
      </geometry>
    </collision>
  </link>
  <joint
    name="joint_8"
    type="continuous">
    <origin
      xyz="-0.58427183482262 -0.707395699999999 0.308828015725114"
      rpy="0 0 0" />
    <parent
      link="rocker_2" />
    <child
      link="wheel_6" />
    <axis
      xyz="0 1 0" />
  </joint>
</robot>