<?xml version="1.0" encoding="utf-8"?>
<!-- This URDF was automatically created by SolidWorks to URDF Exporter! Originally created by Stephen Brawner (brawner@gmail.com) 
     Commit Version: 1.6.0-4-g7f85cfe  Build Version: 1.6.7995.38578
     For more information, please see http://wiki.ros.org/sw_urdf_exporter -->
<robot
  name="Rover">
  <link
    name="chassis">
    <inertial>
      <origin
        xyz="0.280596630449412 0.391929398096866 0.497299040946044"
        rpy="0 0 0" />
      <mass
        value="1.29640563513338" />
      <inertia
        ixx="0.00672846851367381"
        ixy="1.67488363226178E-11"
        ixz="4.18701658746673E-12"
        iyy="0.0141290723043649"
        iyz="4.23106487277759E-11"
        izz="0.0202362014370819" />
    </inertial>
    <visual>
      <origin
        xyz="0 0 0"
        rpy="0 0 0" />
      <geometry>
        <mesh
          filename="package://Rover/meshes/chassis.STL" />
      </geometry>
      <material
        name="">
        <color
          rgba="0.752941176470588 0.752941176470588 0.752941176470588 1" />
      </material>
    </visual>
    <collision>
      <origin
        xyz="0 0 0"
        rpy="0 0 0" />
      <geometry>
        <mesh
          filename="package://Rover/meshes/chassis.STL" />
      </geometry>
    </collision>
  </link>
  <link
    name="rocker_1">
    <inertial>
      <origin
        xyz="-0.0569379504262081 -0.0279401827117303 0.173105600500696"
        rpy="0 0 0" />
      <mass
        value="0.702057959029176" />
      <inertia
        ixx="0.00201938596176855"
        ixy="8.38446274601664E-19"
        ixz="-0.00197087340304265"
        iyy="0.00810448763367223"
        iyz="3.52036066567989E-19"
        izz="0.00646378679421278" />
    </inertial>
    <visual>
      <origin
        xyz="0 0 0"
        rpy="0 0 0" />
      <geometry>
        <mesh
          filename="package://Rover/meshes/rocker_1.STL" />
      </geometry>
      <material
        name="">
        <color
          rgba="0.752941176470588 0.752941176470588 0.752941176470588 1" />
      </material>
    </visual>
    <collision>
      <origin
        xyz="0 0 0"
        rpy="0 0 0" />
      <geometry>
        <mesh
          filename="package://Rover/meshes/rocker_1.STL" />
      </geometry>
    </collision>
  </link>
  <joint
    name="joint_1"
    type="continuous">
    <origin
      xyz="0.256227202845866 0.104049397997044 0.442431681089809"
      rpy="3.14159265358979 0 0" />
    <parent
      link="chassis" />
    <child
      link="rocker_1" />
    <axis
      xyz="0 1 0" />
  </joint>
  <link
    name="wheel_1">
    <inertial>
      <origin
        xyz="-0.000176268265629331 -0.063545275407954 -0.000101180829060271"
        rpy="0 0 0" />
      <mass
        value="3.71098878156725" />
      <inertia
        ixx="0.0272042721492542"
        ixy="4.78292852750308E-05"
        ixz="-4.80095002679056E-05"
        iyy="0.0486688742529404"
        iyz="2.76468584338433E-05"
        izz="0.0272554582911533" />
    </inertial>
    <visual>
      <origin
        xyz="0 0 0"
        rpy="0 0 0" />
      <geometry>
        <mesh
          filename="package://Rover/meshes/wheel_1.STL" />
      </geometry>
      <material
        name="">
        <color
          rgba="0.752941176470588 0.752941176470588 0.752941176470588 1" />
      </material>
    </visual>
    <collision>
      <origin
        xyz="0 0 0"
        rpy="0 0 0" />
      <geometry>
        <mesh
          filename="package://Rover/meshes/wheel_1.STL" />
      </geometry>
    </collision>
  </link>
  <joint
    name="joint_3"
    type="continuous">
    <origin
      xyz="0.566011190291999 0.1316352 0.343614113670245"
      rpy="0 0 0" />
    <parent
      link="rocker_1" />
    <child
      link="wheel_1" />
    <axis
      xyz="0 1 0" />
  </joint>
  <link
    name="wheel_2">
    <inertial>
      <origin
        xyz="0.000178620256626905 -0.0635452759401471 -9.69747179342118E-05"
        rpy="0 0 0" />
      <mass
        value="3.71098882585926" />
      <inertia
        ixx="0.0271986135719232"
        ixy="-4.86694249211029E-05"
        ixz="4.4432824626282E-05"
        iyy="0.048668870619602"
        iyz="2.62407892171943E-05"
        izz="0.0272611104614586" />
    </inertial>
    <visual>
      <origin
        xyz="0 0 0"
        rpy="0 0 0" />
      <geometry>
        <mesh
          filename="package://Rover/meshes/wheel_2.STL" />
      </geometry>
      <material
        name="">
        <color
          rgba="0.752941176470588 0.752941176470588 0.752941176470588 1" />
      </material>
    </visual>
    <collision>
      <origin
        xyz="0 0 0"
        rpy="0 0 0" />
      <geometry>
        <mesh
          filename="package://Rover/meshes/wheel_2.STL" />
      </geometry>
    </collision>
  </link>
  <joint
    name="joint_4"
    type="continuous">
    <origin
      xyz="-0.569418798760428 0.1316347 0.337858198560885"
      rpy="0 0 0" />
    <parent
      link="rocker_1" />
    <child
      link="wheel_2" />
    <axis
      xyz="0 1 0" />
  </joint>
  <link
    name="wheel_3">
    <inertial>
      <origin
        xyz="0.00194962016118483 -0.0675452750876231 0.00121412273220574"
        rpy="0 0 0" />
      <mass
        value="3.71098876791251" />
      <inertia
        ixx="0.0272070703663635"
        ixy="4.70156922027863E-05"
        ixz="-4.9399498887416E-05"
        iyy="0.0486688742503798"
        iyz="2.90088130261499E-05"
        izz="0.0272526600966611" />
    </inertial>
    <visual>
      <origin
        xyz="0 0 0"
        rpy="0 0 0" />
      <geometry>
        <mesh
          filename="package://Rover/meshes/wheel_3.STL" />
      </geometry>
      <material
        name="">
        <color
          rgba="0.752941176470588 0.752941176470588 0.752941176470588 1" />
      </material>
    </visual>
    <collision>
      <origin
        xyz="0 0 0"
        rpy="0 0 0" />
      <geometry>
        <mesh
          filename="package://Rover/meshes/wheel_3.STL" />
      </geometry>
    </collision>
  </link>
  <joint
    name="joint_5"
    type="continuous">
    <origin
      xyz="0.00389311933816788 0.135634699999995 0.348264389277544"
      rpy="0 0 0" />
    <parent
      link="rocker_1" />
    <child
      link="wheel_3" />
    <axis
      xyz="0 1 0" />
  </joint>
  <link
    name="rocker_2">
    <inertial>
      <origin
        xyz="-0.0634016522720201 0.0349398172882701 0.170844109095454"
        rpy="0 0 0" />
      <mass
        value="0.702057959029149" />
      <inertia
        ixx="0.00217365418533618"
        ixy="6.73373283262978E-19"
        ixz="-0.00213217567457792"
        iyy="0.00810448763367225"
        iyz="9.78126874401938E-19"
        izz="0.00630951857064517" />
    </inertial>
    <visual>
      <origin
        xyz="0 0 0"
        rpy="0 0 0" />
      <geometry>
        <mesh
          filename="package://Rover/meshes/rocker_2.STL" />
      </geometry>
      <material
        name="">
        <color
          rgba="0.752941176470588 0.752941176470588 0.752941176470588 1" />
      </material>
    </visual>
    <collision>
      <origin
        xyz="0 0 0"
        rpy="0 0 0" />
      <geometry>
        <mesh
          filename="package://Rover/meshes/rocker_2.STL" />
      </geometry>
    </collision>
  </link>
  <joint
    name="joint_2"
    type="continuous">
    <origin
      xyz="0.257280649253525 0.686809397997044 0.442407585082231"
      rpy="3.14159265358979 0 0" />
    <parent
      link="chassis" />
    <child
      link="rocker_2" />
    <axis
      xyz="0 1 0" />
  </joint>
  <link
    name="wheel_4">
    <inertial>
      <origin
        xyz="0.00194021425049595 0.0675452760210624 0.0012290934521642"
        rpy="0 0 0" />
      <mass
        value="3.71098880202612" />
      <inertia
        ixx="0.0272054221797023"
        ixy="-4.6545735350503E-05"
        ixz="-4.86053275352078E-05"
        iyy="0.0486688742211578"
        iyz="-2.97572117749254E-05"
        izz="0.0272543080141054" />
    </inertial>
    <visual>
      <origin
        xyz="0 0 0"
        rpy="0 0 0" />
      <geometry>
        <mesh
          filename="package://Rover/meshes/wheel_4.STL" />
      </geometry>
      <material
        name="">
        <color
          rgba="0.752941176470588 0.752941176470588 0.752941176470588 1" />
      </material>
    </visual>
    <collision>
      <origin
        xyz="0 0 0"
        rpy="0 0 0" />
      <geometry>
        <mesh
          filename="package://Rover/meshes/wheel_4.STL" />
      </geometry>
    </collision>
  </link>
  <joint
    name="joint_6"
    type="continuous">
    <origin
      xyz="0.550522165589643 -0.128635200000009 0.363405762447953"
      rpy="0 0 0" />
    <parent
      link="rocker_2" />
    <child
      link="wheel_4" />
    <axis
      xyz="0 1 0" />
  </joint>
  <link
    name="wheel_5">
    <inertial>
      <origin
        xyz="0.00190412164591511 0.0675452763004372 0.00128429872637638"
        rpy="0 0 0" />
      <mass
        value="3.7109887931054" />
      <inertia
        ixx="0.0272082525262715"
        ixy="-4.56720854196087E-05"
        ixz="-4.99283758016243E-05"
        iyy="0.0486688742002614"
        iyz="-3.10813718997883E-05"
        izz="0.0272514775785934" />
    </inertial>
    <visual>
      <origin
        xyz="0 0 0"
        rpy="0 0 0" />
      <geometry>
        <mesh
          filename="package://Rover/meshes/wheel_5.STL" />
      </geometry>
      <material
        name="">
        <color
          rgba="0.752941176470588 0.752941176470588 0.752941176470588 1" />
      </material>
    </visual>
    <collision>
      <origin
        xyz="0 0 0"
        rpy="0 0 0" />
      <geometry>
        <mesh
          filename="package://Rover/meshes/wheel_5.STL" />
      </geometry>
    </collision>
  </link>
  <joint
    name="joint_7"
    type="continuous">
    <origin
      xyz="-0.00926565490461811 -0.128635699999999 0.348270005795649"
      rpy="0 0 0" />
    <parent
      link="rocker_2" />
    <child
      link="wheel_5" />
    <axis
      xyz="0 1 0" />
  </joint>
  <link
    name="wheel_6">
    <inertial>
      <origin
        xyz="0.000183308022644324 0.063545275877115 -8.77894032265403E-05"
        rpy="0 0 0" />
      <mass
        value="3.71098880708039" />
      <inertia
        ixx="0.0271974322176279"
        ixy="4.97534168410985E-05"
        ixz="4.36810350456356E-05"
        iyy="0.0486688742475462"
        iyz="-2.40124238018518E-05"
        izz="0.027262298065" />
    </inertial>
    <visual>
      <origin
        xyz="0 0 0"
        rpy="0 0 0" />
      <geometry>
        <mesh
          filename="package://Rover/meshes/wheel_6.STL" />
      </geometry>
      <material
        name="">
        <color
          rgba="0.752941176470588 0.752941176470588 0.752941176470588 1" />
      </material>
    </visual>
    <collision>
      <origin
        xyz="0 0 0"
        rpy="0 0 0" />
      <geometry>
        <mesh
          filename="package://Rover/meshes/wheel_6.STL" />
      </geometry>
    </collision>
  </link>
  <joint
    name="joint_8"
    type="continuous">
    <origin
      xyz="-0.585325281230279 -0.124635699999999 0.308803919717537"
      rpy="0 0 0" />
    <parent
      link="rocker_2" />
    <child
      link="wheel_6" />
    <axis
      xyz="0 1 0" />
  </joint>
</robot>