<?xml version="1.0" encoding="utf-8"?>
<!-- This URDF was automatically created by SolidWorks to URDF Exporter! Originally created by Stephen Brawner (brawner@gmail.com) 
     Commit Version: 1.6.0-4-g7f85cfe  Build Version: 1.6.7995.38578
     For more information, please see http://wiki.ros.org/sw_urdf_exporter -->
<robot
  name="2022_Arm_URDF">
  <link
    name="base_link">
    <inertial>
      <origin
        xyz="0.0749514957283526 0.0634999999999999 0.0191117741265478"
        rpy="0 0 0" />
      <mass
        value="0.2154527360411" />
      <inertia
        ixx="0.000316161341302654"
        ixy="-2.71050543121376E-20"
        ixz="2.37145138846522E-20"
        iyy="0.000430213218560815"
        iyz="-1.57434068015326E-19"
        izz="0.0007449266277053" />
    </inertial>
    <visual>
      <origin
        xyz="0 0 0"
        rpy="0 0 0" />
      <geometry>
        <mesh
          filename="package://rover/rover/simulation/meshes/Arm_2022/base_link.STL" />
      </geometry>
      <material
        name="">
        <color
          rgba="0.792156862745098 0.819607843137255 0.933333333333333 1" />
      </material>
    </visual>
    <collision>
      <origin
        xyz="0 0 0"
        rpy="0 0 0" />
      <geometry>
        <mesh
          filename="package://rover/rover/simulation/meshes/Arm_2022/base_link.STL" />
      </geometry>
    </collision>
  </link>
  <link
    name="Link_1">
    <inertial>
      <origin
        xyz="-0.00336961409672948 0.000135496366357901 -0.0211362751161564"
        rpy="0 0 0" />
      <mass
        value="0.124438490848543" />
      <inertia
        ixx="4.9436489944978E-05"
        ixy="5.27241351093035E-07"
        ixz="1.19210212248392E-05"
        iyy="6.1951078535482E-05"
        iyz="-5.07787736567993E-07"
        izz="5.32151276110618E-05" />
    </inertial>
    <visual>
      <origin
        xyz="0 0 0"
        rpy="0 0 0" />
      <geometry>
        <mesh
	filename="package://rover/rover/simulation/meshes/Arm_2022/Link_1.STL" />
      </geometry>
      <material
        name="">
        <color
          rgba="0.792156862745098 0.819607843137255 0.933333333333333 1" />
      </material>
    </visual>
    <collision>
      <origin
        xyz="0 0 0"
        rpy="0 0 0" />
      <geometry>
        <mesh
	filename="package://rover/rover/simulation/meshes/Arm_2022/Link_1.STL" />
      </geometry>
    </collision>
  </link>
  <joint
    name="Jont_1"
    type="continuous">
    <origin
      xyz="0.0634999999999999 0.0634999999999998 0.073885628993429"
      rpy="0 0 0" />
    <parent
      link="base_link" />
    <child
      link="Link_1" />
    <axis
      xyz="0 0 1" />
  </joint>
  <link
    name="Link_2">
    <inertial>
      <origin
        xyz="-0.00218475630793361 0.030282913954684 0.168261953496061"
        rpy="0 0 0" />
      <mass
        value="0.0977994050531245" />
      <inertia
        ixx="0.00121637285038755"
        ixy="8.35289544838167E-07"
        ixz="-2.08535865552607E-05"
        iyy="0.00123594674557482"
        iyz="8.88283979939617E-07"
        izz="1.98093687311684E-05" />
    </inertial>
    <visual>
      <origin
        xyz="0 0 0"
        rpy="0 0 0" />
      <geometry>
        <mesh
          filename="package://rover/rover/simulation/meshes/Arm_2022/Link_2.STL" />
      </geometry>
      <material
        name="">
        <color
          rgba="0.792156862745098 0.819607843137255 0.933333333333333 1" />
      </material>
    </visual>
    <collision>
      <origin
        xyz="0 0 0"
        rpy="0 0 0" />
      <geometry>
        <mesh
          filename="package://rover/rover/simulation/meshes/Arm_2022/Link_2.STL" />
      </geometry>
    </collision>
  </link>
  <joint
    name="Joint_2"
    type="continuous">
    <origin
      xyz="-0.00128364449465596 -0.0301351731878437 0.0253999999999986"
      rpy="0 0 0" />
    <parent
      link="Link_1" />
    <child
      link="Link_2" />
    <axis
      xyz="-0.042557629329658 -0.99909401368732 0" />
  </joint>
  <link
    name="Link_3">
    <inertial>
      <origin
        xyz="0.15048385069106 0.0217564124633619 0.00115247551879194"
        rpy="0 0 0" />
      <mass
        value="0.141984280956931" />
      <inertia
        ixx="5.95964985675722E-05"
        ixy="5.07938464591886E-05"
        ixz="-3.10414034320994E-05"
        iyy="0.00124988246836639"
        iyz="1.32225564693364E-06"
        izz="0.00120398008301502" />
    </inertial>
    <visual>
      <origin
        xyz="0 0 0"
        rpy="0 0 0" />
      <geometry>
        <mesh
          filename="package://rover/rover/simulation/meshes/Arm_2022/Link_3.STL" />
      </geometry>
      <material
        name="">
        <color
          rgba="0.792156862745098 0.819607843137255 0.933333333333333 1" />
      </material>
    </visual>
    <collision>
      <origin
        xyz="0 0 0"
        rpy="0 0 0" />
      <geometry>
        <mesh
          filename="package://rover/rover/simulation/meshes/Arm_2022/Link_3.STL" />
      </geometry>
    </collision>
  </link>
  <joint
    name="Joint_3"
    type="continuous">
    <origin
      xyz="0.0203458321440578 -0.0010918595926325 0.359423017601817"
      rpy="0 0 0" />
    <parent
      link="Link_2" />
    <child
      link="Link_3" />
    <axis
      xyz="0.0425576293296517 0.999094013687321 0" />
  </joint>
  <link
    name="Link_4">
    <inertial>
      <origin
        xyz="0.0839791711890348 0.0432475895452791 -0.079151958049356"
        rpy="0 0 0" />
      <mass
        value="0.238632261855068" />
      <inertia
        ixx="0.000573749065389909"
        ixy="-4.89763267933332E-05"
        ixz="0.000429213178058777"
        iyy="0.00101632366281932"
        iyz="4.69948822542688E-05"
        izz="0.000609548709163216" />
    </inertial>
    <visual>
      <origin
        xyz="0 0 0"
        rpy="0 0 0" />
      <geometry>
        <mesh
          filename="package://rover/rover/simulation/meshes/Arm_2022/Link_4.STL" />
      </geometry>
      <material
        name="">
        <color
          rgba="0.792156862745098 0.819607843137255 0.933333333333333 1" />
      </material>
    </visual>
    <collision>
      <origin
        xyz="0 0 0"
        rpy="0 0 0" />
      <geometry>
        <mesh
          filename="package://rover/rover/simulation/meshes/Arm_2022/Link_4.STL" />
      </geometry>
    </collision>
  </link>
  <joint
    name="Joint_4"
    type="continuous">
    <origin
      xyz="0.279141869846395 -0.0118903887567749 -0.00167187136799996"
      rpy="0 0 0" />
    <parent
      link="Link_3" />
    <child
      link="Link_4" />
    <axis
      xyz="0.0425576292484878 0.999094013690778 0" />
  </joint>
  <link
    name="Link_5">
    <inertial>
      <origin
        xyz="-0.0213903493992734 0.0009069203040378 -0.0134383433555607"
        rpy="0 0 0" />
      <mass
        value="0.141474277285464" />
      <inertia
        ixx="6.61767833616355E-05"
        ixy="9.38274094042714E-07"
        ixz="2.4359157841955E-05"
        iyy="8.82835567216679E-05"
        iyz="-1.03874093400667E-06"
        izz="6.78878185490211E-05" />
    </inertial>
    <visual>
      <origin
        xyz="0 0 0"
        rpy="0 0 0" />
      <geometry>
        <mesh
          filename="package://rover/rover/simulation/meshes/Arm_2022/Link_5.STL" />
      </geometry>
      <material
        name="">
        <color
          rgba="0.792156862745098 0.819607843137255 0.933333333333333 1" />
      </material>
    </visual>
    <collision>
      <origin
        xyz="0 0 0"
        rpy="0 0 0" />
      <geometry>
        <mesh
          filename="package://rover/rover/simulation/meshes/Arm_2022/Link_5.STL" />
      </geometry>
    </collision>
  </link>
  <joint
    name="Joint_5"
    type="continuous">
    <origin
      xyz="0.188776211964945 0.026150322991645 -0.146743719519598"
      rpy="0 0 0" />
    <parent
      link="Link_4" />
    <child
      link="Link_5" />
    <axis
      xyz="-0.693598744021866 0.0295446853321158 -0.71975544031283" />
  </joint>
  <link
    name="Link_6">
    <inertial>
      <origin
        xyz="0.07734788670601 -0.00314870986467394 -0.0756943478661394"
        rpy="0 0 0" />
      <mass
        value="0.502178404846805" />
      <inertia
        ixx="0.000288930405190543"
        ixy="8.51641656590431E-06"
        ixz="5.47149255506328E-06"
        iyy="0.000416197009730574"
        iyz="2.88842582782739E-06"
        izz="0.000291470816702645" />
    </inertial>
    <visual>
      <origin
        xyz="0 0 0"
        rpy="0 0 0" />
      <geometry>
        <mesh
          filename="package://rover/rover/simulation/meshes/Arm_2022/Link_6.STL" />
      </geometry>
      <material
        name="">
        <color
          rgba="0.792156862745098 0.819607843137255 0.933333333333333 1" />
      </material>
    </visual>
    <collision>
      <origin
        xyz="0 0 0"
        rpy="0 0 0" />
      <geometry>
        <mesh
          filename="package://rover/rover/simulation/meshes/Arm_2022/Link_6.STL" />
      </geometry>
    </collision>
  </link>
  <joint
    name="Joint_6"
    type="continuous">
    <origin
      xyz="0.028599 -0.0012182 -0.061708"
      rpy="0 0 0" />
    <parent
      link="Link_5" />
    <child
      link="Link_6" />
    <axis
      xyz="0.7191 -0.030631 -0.69423" />
  </joint>
</robot>
