<?xml version="1.0"?>

<robot name="robot_base">
  <link name="base_link">
    <inertial>
      <origin
        xyz="0.0030946 4.78250032638821E-11 0.053305"
        rpy="0 0 0" />
      <mass
        value="47.873" />
      <inertia
        ixx="0.774276574699151"
        ixy="-1.03781944357671E-10"
        ixz="0.00763014265820928"
        iyy="1.64933255189991"
        iyz="1.09578155845563E-12"
        izz="2.1239326987473" />
    </inertial>
    <visual>
      <origin
        xyz="0 0 0"
        rpy="1.5707963267949 0 3.14" />
      <geometry>
        <mesh filename="package://mobile_manipulator_body/meshes/robot_base.stl" />
      </geometry>
      <material
        name="">
        <color
          rgba="0.79216 0.81961 0.93333 1" />
      </material>
    </visual>
    <collision>
      <origin
        xyz="0 0 0"
        rpy="1.5707963267949 0 3.14" />
      <geometry>
        <mesh filename="package://mobile_manipulator_body/meshes/robot_base.stl" />
      </geometry>
    </collision>
  </link>

  <link name="front_left_wheel">
    <inertial>
      <origin
        xyz="-4.1867E-18 0.0068085 -1.65658661799998E-18"
        rpy="0 0 0" />
      <mass
        value="2.6578" />
      <inertia
        ixx="0.00856502765719703"
        ixy="1.5074118157338E-19"
        ixz="-4.78150098725052E-19"
        iyy="0.013670640432096"
        iyz="-2.68136447099727E-19"
        izz="0.00856502765719703" />
    </inertial>
    <visual>
      <origin
        xyz="0 0 0"
        rpy="1.5707963267949 0 0" />
      <geometry>
        <mesh filename="package://mobile_manipulator_body/meshes/wheel.stl" />
      </geometry>
      <material
        name="">
        <color
          rgba="0.79216 0.81961 0.93333 1" />
      </material>
    </visual>
    <collision>
      <origin
        xyz="0 0 0"
        rpy="1.5707963267949 0 0" />
      <geometry>
        <mesh filename="package://mobile_manipulator_body/meshes/wheel.stl" />
      </geometry>
    </collision>
  </link>

  <link name="front_right_wheel">
    <inertial>
      <origin
        xyz="-4.1867E-18 0.0068085 -1.65658661799998E-18"
        rpy="0 0 0" />
      <mass
        value="2.6578" />
      <inertia
        ixx="0.00856502765719703"
        ixy="1.5074118157338E-19"
        ixz="-4.78150098725052E-19"
        iyy="0.013670640432096"
        iyz="-2.68136447099727E-19"
        izz="0.00856502765719703" />
    </inertial>
    <visual>
      <origin
        xyz="0 0 0"
        rpy="1.5707963267949 0 0" />
      <geometry>
        <mesh filename="package://mobile_manipulator_body/meshes/wheel.stl" />
      </geometry>
      <material
        name="">
        <color
          rgba="0.79216 0.81961 0.93333 1" />
      </material>
    </visual>
    <collision>
      <origin
        xyz="0 0 0"
        rpy="1.5707963267949 0 0" />
      <geometry>
        <mesh filename="package://mobile_manipulator_body/meshes/wheel.stl" />
      </geometry>
    </collision>
  </link>

  <link name="rear_left_wheel">
    <inertial>
      <origin
        xyz="-4.1867E-18 0.0068085 -1.65658661799998E-18"
        rpy="0 0 0" />
      <mass
        value="2.6578" />
      <inertia
        ixx="0.00856502765719703"
        ixy="1.5074118157338E-19"
        ixz="-4.78150098725052E-19"
        iyy="0.013670640432096"
        iyz="-2.68136447099727E-19"
        izz="0.00856502765719703" />
    </inertial>
    <visual>
      <origin
        xyz="0 0 0"
        rpy="1.5707963267949 0 0" />
      <geometry>
        <mesh filename="package://mobile_manipulator_body/meshes/wheel.stl" />
      </geometry>
      <material
        name="">
        <color
          rgba="0.79216 0.81961 0.93333 1" />
      </material>
    </visual>
    <collision>
      <origin
        xyz="0 0 0"
        rpy="1.5707963267949 0 0" />
      <geometry>
        <mesh filename="package://mobile_manipulator_body/meshes/wheel.stl" />
      </geometry>
    </collision>
  </link>

  <link name="rear_right_wheel">
    <inertial>
      <origin
        xyz="-4.1867E-18 0.0068085 -1.65658661799998E-18"
        rpy="0 0 0" />
      <mass
        value="2.6578" />
      <inertia
        ixx="0.00856502765719703"
        ixy="1.5074118157338E-19"
        ixz="-4.78150098725052E-19"
        iyy="0.013670640432096"
        iyz="-2.68136447099727E-19"
        izz="0.00856502765719703" />
    </inertial>
    <visual>
      <origin
        xyz="0 0 0"
        rpy="1.5707963267949 0 0" />
      <geometry>
        <mesh filename="package://mobile_manipulator_body/meshes/wheel.stl" />
      </geometry>
      <material
        name="">
        <color
          rgba="0.79216 0.81961 0.93333 1" />
      </material>
    </visual>
    <collision>
      <origin
        xyz="0 0 0"
        rpy="1.5707963267949 0 0" />
      <geometry>
        <mesh filename="package://mobile_manipulator_body/meshes/wheel.stl" />
      </geometry>
    </collision>
  </link>

  <link name="imu_link">
    <collision>
      <origin xyz="0 0 0" rpy="0 0 0"/>
      <geometry>
    <box size="0.05 0.05 0.05"/>
      </geometry>
    </collision>

    <visual>
      <origin xyz="0 0 0" rpy="0 0 0"/>
      <geometry>
    <box size="0.05 0.05 0.05"/>
      </geometry>
      <material name="red"/>
    </visual>

    <inertial>
      <mass value="1e-5" />
      <origin xyz="0 0 0" rpy="0 0 0"/>
      <inertia ixx="1e-6" ixy="0" ixz="0" iyy="1e-6" iyz="0" izz="1e-6" />
    </inertial>
  </link>

  <link name="gps_link">
    <collision>
      <origin xyz="0 0 0" rpy="0 0 0"/>
      <geometry>
    <box size="0.05 0.05 0.05"/>
      </geometry>
    </collision>

    <visual>
      <origin xyz="0 0 0" rpy="0 0 0"/>
      <geometry>
    <box size="0.05 0.05 0.05"/>
      </geometry>
      <material name="red"/>
    </visual>

    <inertial>
      <mass value="1e-5" />
      <origin xyz="0 0 0" rpy="0 0 0"/>
      <inertia ixx="1e-6" ixy="0" ixz="0" iyy="1e-6" iyz="0" izz="1e-6" />
    </inertial>
  </link>
  <link name="lidar_link">
    <inertial>
      <mass value="0.425"/>
      <origin xyz="0 0 0.03675" rpy="0 0 0" />
      <inertia ixx="0.000308429" ixy="0" ixz="0"
                iyy="0.000308429" iyz="0" izz="0.00034589"/>
    </inertial>
    <collision>
      <origin xyz="0 0 0.03675" rpy="0 0 0" />
      <geometry>
        <mesh filename="package://mobile_manipulator_body/meshes/os1_64.stl" />
      </geometry>
    </collision>
    <visual>
      <origin xyz="0 0 0" rpy="0 0 0"/>
      <geometry>
        <mesh filename="package://mobile_manipulator_body/meshes/os1_64.stl" />
      </geometry>
    </visual>
  </link>

  <joint name="lidar_joint" type="fixed">
      <parent link="base_link"/>
      <child link="lidar_link"/>
      <axis
      xyz="0 0 0" />
      <origin
      xyz="0.0 0 0.278189004081027"
      rpy="0 0 0" />
  </joint> 

  <joint name="gps_joint" type="fixed">
    <origin
      xyz="0.0 0 0.278189004081027"
      rpy="0 0 0" />
    <parent
      link="base_link" />
    <child
      link="gps_link" />
    <axis
      xyz="0 0 0" />
  </joint>


  <joint name="imu_joint" type="fixed">
    <origin
      xyz="0.0 0 0.0"
      rpy="1.5707963267949 0 0" />
    <parent
      link="base_link" />
    <child
      link="imu_link" />
    <axis
      xyz="0 0 0" />
  </joint>

  <joint name="front_left_wheel_joint" type="continuous">
    <axis xyz="0 1 0"/>
    <parent link ="base_link"/>
    <child link ="front_left_wheel"/>
    <origin rpy ="0 0 0" xyz= "0.220 0.250 0"/>
  </joint>


  <joint name="front_right_wheel_joint" type="continuous">
    <axis xyz="0 1 0"/>
    <parent link ="base_link"/>
    <child link ="front_right_wheel"/>
    <origin rpy ="0 0 0" xyz= "0.220 -0.250 0"/>
  </joint>

  <joint name="rear_left_wheel_joint" type="continuous">
    <axis xyz="0 1 0"/>
    <parent link ="base_link"/>
    <child link ="rear_left_wheel"/>
    <origin rpy ="0 0 0" xyz= "-0.220 0.250 0"/>
  </joint>

  <joint name="rear_right_wheel_joint" type="continuous">
    <axis xyz="0 1 0"/>
    <parent link ="base_link"/>
    <child link ="rear_right_wheel"/>
    <origin rpy ="0 0 0" xyz= "-0.220 -0.250 0"/>
  </joint>
<!--######################################################################-->
  <gazebo>
    <plugin name="gazebo_ros_control" filename="libgazebo_ros_control.so">
      <robotNamespace>/</robotNamespace>
      <controlPeriod>0.001</controlPeriod>
      <legacyModeNS>false</legacyModeNS>
    </plugin>
  </gazebo>
<!--######################################################################-->
<!-- 
  <gazebo>
      <plugin name="imu_plugin" filename="libgazebo_ros_imu.so">
        <alwaysOn>true</alwaysOn>
        <bodyName>base_footprint</bodyName>
        <topicName>imu</topicName>
        <serviceName>imu_service</serviceName>
        <gaussianNoise>0.0</gaussianNoise>
        <updateRate>20.0</updateRate>
      </plugin>
  </gazebo> -->
<!--
  <gazebo reference="imu_link">
    <gravity>true</gravity>
    <sensor name="imu_sensor" type="imu">
      <always_on>true</always_on>
      <update_rate>100</update_rate>
      <visualize>true</visualize>
      <topic>__default_topic__</topic>
      <plugin filename="libgazebo_ros_imu_sensor.so" name="imu_plugin">
        <topicName>imu</topicName>
        <bodyName>imu_link</bodyName>
        <updateRateHZ>10.0</updateRateHZ>
        <gaussianNoise>0.0</gaussianNoise>
        <xyzOffset>0 0 0</xyzOffset>
        <rpyOffset>0 0 0</rpyOffset>
        <frameName>imu_link</frameName>
        <initialOrientationAsReference>false</initialOrientationAsReference>
      </plugin>
      <pose>0 0 0 0 0 0</pose>
    </sensor>
  </gazebo> -->
<gazebo>
  <plugin filename="libhector_gazebo_ros_imu.so"
            name="hector_imu_plugin" >
    <alwaysOn>true</alwaysOn>
    <bodyName>imu_link</bodyName>
    <topicName>imu</topicName>
    <serviceName>/imu/calibrate</serviceName>
    <gaussianNoise>0.0</gaussianNoise>
    <updateRate>5.0</updateRate>
    <frameName>imu_link</frameName>
    <!-- Accelerometer config, 3 values are corresponding
    to x,y,z axis respectively -->
    <accelOffset>0 0 0 </accelOffset>
    <accelGaussianNoise>0 0 0</accelGaussianNoise>
    <accelDrift>0 0 0 </accelDrift>
    <accelDriftFrequency>0 0 0</accelDriftFrequency>
    <!-- Gyroscope config -->
    <rateOffset>0 0 0</rateOffset>
    <rateGaussianNoise> 0 0 0</rateGaussianNoise>
    <rateDrift>0 0 0 </rateDrift>
    <rateDriftFrequency> 0 0 0</rateDriftFrequency>
    <!-- Separate error model for YAW angle -->
    <yawOffset> 0 </yawOffset>
    <yawGaussianNoise> 0 </yawGaussianNoise>
    <yawDrift> 0 </yawDrift>
    <yawDriftFrequency> 0 </yawDriftFrequency> 
  </plugin>
</gazebo>


<!--######################################################################-->

<gazebo>
    <plugin name="gps_controller" filename="libhector_gazebo_ros_gps.so">
        <robotNamespace>/</robotNamespace>
        <updateRate>40</updateRate>
        <bodyName>base_link</bodyName>
        <frameId>base_link</frameId>
        <topicName>navsat/fix</topicName>
        <velocityTopicName>navsat/vel</velocityTopicName>
        <referenceLatitude>50.0</referenceLatitude>
        <referenceLongitude>60.0</referenceLongitude>
        <referenceHeading>0</referenceHeading>
        <referenceAltitude>0</referenceAltitude>
        <drift>0.0001 0.0001 0.0001</drift>
    </plugin>
</gazebo>

<!--######################################################################-->

<gazebo reference="lidar_link">
    <sensor type="gpu_ray" name="os1_lidar">
      <pose>0 0 0 0 0 0</pose>
          <visualize>true</visualize>
          <update_rate>10</update_rate>
          <ray>
            <scan>
              <horizontal>
                <samples>512</samples>
                <resolution>1</resolution>
                <min_angle>-3.141529</min_angle>
                <max_angle>3.141529</max_angle>
              </horizontal>
              <vertical>
                <samples>64</samples>
                <resolution>1</resolution>
                <min_angle>-3.141529</min_angle>
                <max_angle>-3.141529</max_angle>
              </vertical>
            </scan>
            <range>
              <min>0.9</min>
              <max>75.0</max>
              <resolution>0.03</resolution>
            </range>
          </ray>
      <plugin name="gazebo_ros_head_hokuyo_controller" filename="libgazebo_ros_gpu_laser.so">
        <topicName>/rrbot/laser/scan</topicName>
        <frameName>hokuyo_link</frameName>
      </plugin>
    </sensor>
</gazebo>

<!--######################################################################-->

<gazebo>
      <plugin name="diff_drive_controller" filename="libgazebo_ros_diff_drive.so">
        <legacyMode>false</legacyMode>
        <alwaysOn>true</alwaysOn>
        <updateRate>1000.0</updateRate>
        <leftJoint>front_left_wheel_joint, rear_left_wheel_joint</leftJoint>
        <rightJoint>front_right_wheel_joint, rear_right_wheel_joint</rightJoint>
        <wheelSeparation>0.5</wheelSeparation>
        <wheelDiameter>0.2</wheelDiameter>
        <wheelTorque>10</wheelTorque>
        <publishTf>1</publishTf>
        <odometryFrame>map</odometryFrame>
        <commandTopic>cmd_vel</commandTopic>
        <odometryTopic>odom</odometryTopic>
        <robotBaseFrame>base_link</robotBaseFrame>
        <wheelAcceleration>2.8</wheelAcceleration>
        <publishWheelJointState>true</publishWheelJointState>
        <publishWheelTF>false</publishWheelTF>
        <odometrySource>world</odometrySource>
        <rosDebugLevel>Debug</rosDebugLevel>
      </plugin>
</gazebo>
<!--######################################################################-->
<gazebo reference="front_left_wheel">
 <mu1 value="1.0"/>
 <mu2 value="1.0"/>
 <kp value="10000000.0" />
 <kd value="1.0" />
 <fdir1 value="1 0 0"/>
</gazebo>

<gazebo reference="front_right_wheel">
 <mu1 value="1.0"/>
 <mu2 value="1.0"/>
 <kp value="10000000.0" />
 <kd value="1.0" />
 <fdir1 value="1 0 0"/>
</gazebo>

<gazebo reference="rear_left_wheel">
 <mu1 value="1.0"/>
 <mu2 value="1.0"/>
 <kp value="10000000.0" />
 <kd value="1.0" />
 <fdir1 value="1 0 0"/>
</gazebo>

<gazebo reference="rear_left_wheel">
 <mu1 value="1.0"/>
 <mu2 value="1.0"/>
 <kp value="10000000.0" />
 <kd value="1.0" />
 <fdir1 value="1 0 0"/>
</gazebo>
<!--######################################################################-->
<transmission name="front_left_wheel_trans" type="SimpleTransmission">
  <type>transmission_interface/SimpleTransmission</type>
  <actuator name="front_left_wheel_motor">
   <hardwareInterface>hardware_interface/VelocityJointInterface</hardwareInterface>
   <mechanicalReduction>1</mechanicalReduction>
  </actuator>
  <joint name="front_left_wheel_joint">
   <hardwareInterface>hardware_interface/VelocityJointInterface</hardwareInterface>
  </joint>
</transmission>

<transmission name="front_right_wheel_trans" type="SimpleTransmission">
  <type>transmission_interface/SimpleTransmission</type>
  <actuator name="front_right_wheel_motor">
   <hardwareInterface>hardware_interface/VelocityJointInterface</hardwareInterface>
   <mechanicalReduction>1</mechanicalReduction>
  </actuator>
  <joint name="front_right_wheel_joint">
   <hardwareInterface>hardware_interface/VelocityJointInterface</hardwareInterface>
  </joint>
</transmission>

<transmission name="rear_left_wheel_trans" type="SimpleTransmission">
  <type>transmission_interface/SimpleTransmission</type>
  <actuator name="rear_left_wheel_motor">
   <hardwareInterface>hardware_interface/VelocityJointInterface</hardwareInterface>
   <mechanicalReduction>1</mechanicalReduction>
  </actuator>
  <joint name="rear_left_wheel_joint">
   <hardwareInterface>hardware_interface/VelocityJointInterface</hardwareInterface>
  </joint>
</transmission>

<transmission name="rear_right_wheel_trans" type="SimpleTransmission">
  <type>transmission_interface/SimpleTransmission</type>
  <actuator name="rear_right_wheel_motor">
   <hardwareInterface>hardware_interface/VelocityJointInterface</hardwareInterface>
   <mechanicalReduction>1</mechanicalReduction>
  </actuator>
  <joint name="rear_right_wheel_joint">
   <hardwareInterface>hardware_interface/VelocityJointInterface</hardwareInterface>
  </joint>
</transmission>
<!--######################################################################-->
</robot>

