<?xml version="1.0" encoding="utf-8"?>
<!-- This URDF was automatically created by SolidWorks to URDF Exporter! Originally created by Stephen Brawner (brawner@gmail.com) 
     Commit Version: 1.6.0-4-g7f85cfe  Build Version: 1.6.7995.38578
     For more information, please see http://wiki.ros.org/sw_urdf_exporter -->
<robot
  name="rover">
  <link
    name="chassis">
    <inertial>
      <origin
        xyz="0.280596630449412 0.391929398096866 0.497299040946044"
        rpy="0 0 0" />
      <mass
        value="1.29640563513338" />
      <inertia
        ixx="0.00672846851367381"
        ixy="1.67488363226178E-11"
        ixz="4.18701658746673E-12"
        iyy="0.0141290723043649"
        iyz="4.23106487277759E-11"
        izz="0.0202362014370819" />
    </inertial>
    <visual>
      <origin
        xyz="0 0 0"
        rpy="0 0 0" />
      <geometry>
        <mesh
          filename="package://rover/rover/simulation/meshes/chassis.STL" />
      </geometry>
      <material
        name="">
        <color
          rgba="0.752941176470588 0.752941176470588 0.752941176470588 1" />
      </material>
    </visual>
    <collision>
      <origin
        xyz="0 0 0"
        rpy="0 0 0" />
      <geometry>
        <mesh
          filename="package://rover/rover/simulation/meshes/chassis.STL" />
      </geometry>
    </collision>
  </link>
  <link
    name="right_rocker">
    <inertial>
      <origin
        xyz="-0.0569379504262081 -0.0279401827117303 0.173105600500696"
        rpy="0 0 0" />
      <mass
        value="0.702057959029176" />
      <inertia
        ixx="0.00201938596176855"
        ixy="8.38446274601664E-19"
        ixz="-0.00197087340304265"
        iyy="0.00810448763367223"
        iyz="3.52036066567989E-19"
        izz="0.00646378679421278" />
    </inertial>
    <visual>
      <origin
        xyz="0 0 0"
        rpy="0 0 0" />
      <geometry>
        <mesh
          filename="package://rover/rover/simulation/meshes/rocker_1.STL" />
      </geometry>
      <material
        name="">
        <color
          rgba="0.752941176470588 0.752941176470588 0.752941176470588 1" />
      </material>
    </visual>
    <collision>
      <origin
        xyz="0 0 0"
        rpy="0 0 0" />
      <geometry>
        <mesh
          filename="package://rover/simulation/meshes/rocker_1.STL" />
      </geometry>
    </collision>
  </link>
  <joint
    name="chassis_right_rocker_joint"
    type="fixed">
    <origin
      xyz="0.256227202845866 0.104049397997044 0.442431681089809"
      rpy="3.14159265358979 0 0" />
    <parent
      link="chassis" />
    <child
      link="right_rocker" />
    <axis
      xyz="0 1 0" />
  </joint>
  <link
    name="front_right_wheel">
    <inertial>
      <origin
        xyz="-0.000176268265629331 -0.063545275407954 -0.000101180829060271"
        rpy="0 0 0" />
      <mass
        value="3.71098878156725" />
      <inertia
        ixx="0.0272042721492542"
        ixy="4.78292852750308E-05"
        ixz="-4.80095002679056E-05"
        iyy="0.0486688742529404"
        iyz="2.76468584338433E-05"
        izz="0.0272554582911533" />
    </inertial>
    <visual>
      <origin
        xyz="0 0 0"
        rpy="0 0 0" />
      <geometry>
        <mesh
          filename="package://rover/rover/simulation/meshes/wheel_1.STL" />
      </geometry>
      <material
        name="">
        <color
          rgba="0.752941176470588 0.752941176470588 0.752941176470588 1" />
      </material>
    </visual>
    <collision>
      <origin
        xyz="0 0 0"
        rpy="0 0 0" />
      <geometry>
        <mesh
          filename="package://rover/rover/simulation/meshes/wheel_1.STL" />
      </geometry>
    </collision>
  </link>
  <joint
    name="front_right_wheel_joint"
    type="continuous">
    <origin
      xyz="0.566011190291999 0.1316352 0.343614113670245"
      rpy="0 0 0" />
    <parent
      link="right_rocker" />
    <child
      link="front_right_wheel" />
    <axis
      xyz="0 1 0" />
  </joint>
  <link
    name="rear_right_wheel">
    <inertial>
      <origin
        xyz="0.000178620256626905 -0.0635452759401471 -9.69747179342118E-05"
        rpy="0 0 0" />
      <mass
        value="3.71098882585926" />
      <inertia
        ixx="0.0271986135719232"
        ixy="-4.86694249211029E-05"
        ixz="4.4432824626282E-05"
        iyy="0.048668870619602"
        iyz="2.62407892171943E-05"
        izz="0.0272611104614586" />
    </inertial>
    <visual>
      <origin
        xyz="0 0 0"
        rpy="0 0 0" />
      <geometry>
        <mesh
          filename="package://rover/rover/simulation/meshes/wheel_2.STL" />
      </geometry>
      <material
        name="">
        <color
          rgba="0.752941176470588 0.752941176470588 0.752941176470588 1" />
      </material>
    </visual>
    <collision>
      <origin
        xyz="0 0 0"
        rpy="0 0 0" />
      <geometry>
        <mesh
          filename="package://rover/rover/simulation/meshes/wheel_2.STL" />
      </geometry>
    </collision>
  </link>
  <joint
    name="rear_right_wheel_joint"
    type="continuous">
    <origin
      xyz="-0.569418798760428 0.1316347 0.337858198560885"
      rpy="0 0 0" />
    <parent
      link="right_rocker" />
    <child
      link="rear_right_wheel" />
    <axis
      xyz="0 1 0" />
  </joint>
  <link
    name="middle_right_wheel">
    <inertial>
      <origin
        xyz="0.00194962016118483 -0.0675452750876231 0.00121412273220574"
        rpy="0 0 0" />
      <mass
        value="3.71098876791251" />
      <inertia
        ixx="0.0272070703663635"
        ixy="4.70156922027863E-05"
        ixz="-4.9399498887416E-05"
        iyy="0.0486688742503798"
        iyz="2.90088130261499E-05"
        izz="0.0272526600966611" />
    </inertial>
    <visual>
      <origin
        xyz="0 0 0"
        rpy="0 0 0" />
      <geometry>
        <mesh
          filename="package://rover/rover/simulation/meshes/wheel_3.STL" />
      </geometry>
      <material
        name="">
        <color
          rgba="0.752941176470588 0.752941176470588 0.752941176470588 1" />
      </material>
    </visual>
    <collision>
      <origin
        xyz="0 0 0"
        rpy="0 0 0" />
      <geometry>
        <mesh
          filename="package://rover/rover/simulation/meshes/wheel_3.STL" />
      </geometry>
    </collision>
  </link>
  <joint
    name="middle_right_wheel_joint"
    type="continuous">
    <origin
      xyz="0.00389311933816788 0.135634699999995 0.348264389277544"
      rpy="0 0 0" />
    <parent
      link="right_rocker" />
    <child
      link="middle_right_wheel" />
    <axis
      xyz="0 1 0" />
  </joint>
  <link
    name="left_rocker">
    <inertial>
      <origin
        xyz="-0.0634016522720201 0.0349398172882701 0.170844109095454"
        rpy="0 0 0" />
      <mass
        value="0.702057959029149" />
      <inertia
        ixx="0.00217365418533618"
        ixy="6.73373283262978E-19"
        ixz="-0.00213217567457792"
        iyy="0.00810448763367225"
        iyz="9.78126874401938E-19"
        izz="0.00630951857064517" />
    </inertial>
    <visual>
      <origin
        xyz="0 0 0"
        rpy="0 0 0" />
      <geometry>
        <mesh
          filename="package://rover/rover/simulation/meshes/rocker_2.STL" />
      </geometry>
      <material
        name="">
        <color
          rgba="0.752941176470588 0.752941176470588 0.752941176470588 1" />
      </material>
    </visual>
    <collision>
      <origin
        xyz="0 0 0"
        rpy="0 0 0" />
      <geometry>
        <mesh
          filename="package://rover/rover/simulation/meshes/rocker_2.STL" />
      </geometry>
    </collision>
  </link>
  <joint
    name="chassis_left_rocker_joint"
    type="fixed">
    <origin
      xyz="0.257280649253525 0.686809397997044 0.442407585082231"
      rpy="3.14159265358979 0 0" />
    <parent
      link="chassis" />
    <child
      link="left_rocker" />
    <axis
      xyz="0 1 0" />
  </joint>
  <link
    name="front_left_wheel">
    <inertial>
      <origin
        xyz="0.00194021425049595 0.0675452760210624 0.0012290934521642"
        rpy="0 0 0" />
      <mass
        value="3.71098880202612" />
      <inertia
        ixx="0.0272054221797023"
        ixy="-4.6545735350503E-05"
        ixz="-4.86053275352078E-05"
        iyy="0.0486688742211578"
        iyz="-2.97572117749254E-05"
        izz="0.0272543080141054" />
    </inertial>
    <visual>
      <origin
        xyz="0 0 0"
        rpy="0 0 0" />
      <geometry>
        <mesh
          filename="package://rover/rover/simulation/meshes/wheel_4.STL" />
      </geometry>
      <material
        name="">
        <color
          rgba="0.752941176470588 0.752941176470588 0.752941176470588 1" />
      </material>
    </visual>
    <collision>
      <origin
        xyz="0 0 0"
        rpy="0 0 0" />
      <geometry>
        <mesh
          filename="package://rover/rover/simulation/meshes/wheel_4.STL" />
      </geometry>
    </collision>
  </link>

  <joint
    name="front_left_wheel_joint"
    type="continuous">
    <origin
      xyz="0.550522165589643 -0.128635200000009 0.363405762447953"
      rpy="0 0 0" />
    <parent
      link="left_rocker" />
    <child
      link="front_left_wheel" />
    <axis
      xyz="0 1 0" />
  </joint>
  <link
    name="middle_left_wheel">
    <inertial>
      <origin
        xyz="0.00190412164591511 0.0675452763004372 0.00128429872637638"
        rpy="0 0 0" />
      <mass
        value="3.7109887931054" />
      <inertia
        ixx="0.0272082525262715"
        ixy="-4.56720854196087E-05"
        ixz="-4.99283758016243E-05"
        iyy="0.0486688742002614"
        iyz="-3.10813718997883E-05"
        izz="0.0272514775785934" />
    </inertial>
    <visual>
      <origin
        xyz="0 0 0"
        rpy="0 0 0" />
      <geometry>
        <mesh
          filename="package://rover/rover/simulation/meshes/wheel_5.STL" />
      </geometry>
      <material
        name="">
        <color
          rgba="0.752941176470588 0.752941176470588 0.752941176470588 1" />
      </material>
    </visual>
    <collision>
      <origin
        xyz="0 0 0"
        rpy="0 0 0" />
      <geometry>
        <mesh
          filename="package://rover/rover/simulation/meshes/wheel_5.STL" />
      </geometry>
    </collision>
  </link>
  <joint
    name="middle_left_wheel_joint"
    type="continuous">
    <origin
      xyz="-0.00926565490461811 -0.128635699999999 0.348270005795649"
      rpy="0 0 0" />
    <parent
      link="left_rocker" />
    <child
      link="middle_left_wheel" />
    <axis
      xyz="0 1 0" />
  </joint>
  <link
    name="rear_left_wheel">
    <inertial>
      <origin
        xyz="0.000183308022644324 0.063545275877115 -8.77894032265403E-05"
        rpy="0 0 0" />
      <mass
        value="3.71098880708039" />
      <inertia
        ixx="0.0271974322176279"
        ixy="4.97534168410985E-05"
        ixz="4.36810350456356E-05"
        iyy="0.0486688742475462"
        iyz="-2.40124238018518E-05"
        izz="0.027262298065" />
    </inertial>
    <visual>
      <origin
        xyz="0 0 0"
        rpy="0 0 0" />
      <geometry>
        <mesh
          filename="package://rover/rover/simulation/meshes/wheel_6.STL" />
      </geometry>
      <material
        name="">
        <color
          rgba="0.752941176470588 0.752941176470588 0.752941176470588 1" />
      </material>
    </visual>
    <collision>
      <origin
        xyz="0 0 0"
        rpy="0 0 0" />
      <geometry>
        <mesh
          filename="package://rover/rover/simulation/meshes/wheel_6.STL" />
      </geometry>
    </collision>
  </link>
  <joint
    name="rear_left_wheel_joint"
    type="continuous">
    <origin
      xyz="-0.585325281230279 -0.124635699999999 0.308803919717537"
      rpy="0 0 0" />
    <parent
      link="left_rocker" />
    <child
      link="rear_left_wheel" />
    <axis
      xyz="0 1 0" />
  </joint>

  <link name="imu_link">
    <collision>
      <origin xyz="0 0 0" rpy="0 0 0"/>
      <geometry>
    <box size="0.05 0.05 0.05"/>
      </geometry>
    </collision>

    <visual>
      <origin xyz="0 0 0" rpy="0 0 0"/>
      <geometry>
    <box size="0.05 0.05 0.05"/>
      </geometry>
      <material name="red"/>
    </visual>

    <inertial>
      <mass value="1e-5" />
      <origin xyz="0 0 0" rpy="0 0 0"/>
      <inertia ixx="1e-6" ixy="0" ixz="0" iyy="1e-6" iyz="0" izz="1e-6" />
    </inertial>
  </link>


  <joint name="imu_joint" type="fixed">
    <origin
      xyz="0.280596630449412 0.391929398096866 0.497299040946044"
      rpy="1.5707963267949 0 0" />
    <parent
      link="chassis" />
    <child
      link="imu_link" />
    <axis
      xyz="0 0 0" />
  </joint>

  <link name="gps_link">
    <collision>
      <origin xyz="0 0 0" rpy="0 0 0"/>
      <geometry>
    <box size="0.05 0.05 0.05"/>
      </geometry>
    </collision>

    <visual>
      <origin xyz="0 0 0" rpy="0 0 0"/>
      <geometry>
    <box size="0.05 0.05 0.05"/>
      </geometry>
      <material name="red"/>
    </visual>

    <inertial>
      <mass value="1e-5" />
      <origin xyz="0 0 0" rpy="0 0 0"/>
      <inertia ixx="1e-6" ixy="0" ixz="0" iyy="1e-6" iyz="0" izz="1e-6" />
    </inertial>
  </link>

  <joint name="gps_joint" type="fixed">
    <origin
      xyz="0.280596630449412 0.391929398096866 0.278189004081027" 
      rpy="0 0 0" />
    <parent
      link="chassis" />
    <child
      link="gps_link" />
    <axis
      xyz="0 0 0" />
  </joint>

  <link name="lidar_link">
    <inertial>
      <mass value="0.425"/>
      <origin xyz="0 0 0.03675" rpy="0 0 0" />
      <inertia ixx="0.000308429" ixy="0" ixz="0"
                iyy="0.000308429" iyz="0" izz="0.00034589"/>
    </inertial>
    <collision>
      <origin xyz="0 0 0.03675" rpy="0 0 0" />
      <geometry>
        <mesh filename="package://rover/rover/simulation/meshes/os1_64.stl" />
      </geometry>
    </collision>
    <visual>
      <origin xyz="0 0 0" rpy="0 0 0"/>
      <geometry>
        <mesh filename="package://rover/rover/simulation/meshes/os1_64.stl" />
      </geometry>
    </visual>
  </link>

  <joint name="lidar_joint" type="fixed">
      <parent link="chassis"/>
      <child link="lidar_link"/>
      <axis
      xyz="0 0 0" />
      <origin
      xyz="0.280596630449412 0.391929398096866 0.278189004081027"
      rpy="0 0 0" />
  </joint> 

  <gazebo>
    <plugin name="gazebo_ros_control" filename="libgazebo_ros_control.so">
      <robotNamespace>/</robotNamespace>
      <controlPeriod>0.001</controlPeriod>
      <legacyModeNS>false</legacyModeNS>
    </plugin>
  </gazebo>
  <gazebo>
      <plugin name="diff_drive_controller" filename="libgazebo_ros_diff_drive.so">
        <legacyMode>false</legacyMode>
        <alwaysOn>true</alwaysOn>
        <updateRate>1000.0</updateRate>
        <leftJoint>front_left_wheel_joint, middle_left_wheel_joint, rear_left_wheel_joint</leftJoint>
        <rightJoint>front_right_wheel_joint, middle_right_wheel_joint, rear_right_wheel_joint</rightJoint>
        <wheelSeparation>0.5</wheelSeparation>
        <wheelDiameter>0.2</wheelDiameter>
        <wheelTorque>10</wheelTorque>
        <publishTf>1</publishTf>
        <odometryFrame>map</odometryFrame>
        <commandTopic>cmd_vel</commandTopic> 
        <odometryTopic>odom</odometryTopic>
        <robotBaseFrame>chassis</robotBaseFrame>
        <wheelAcceleration>2.8</wheelAcceleration>
        <publishWheelJointState>true</publishWheelJointState>
        <publishWheelTF>false</publishWheelTF>
        <odometrySource>world</odometrySource>
        <rosDebugLevel>Debug</rosDebugLevel>
      </plugin>
  </gazebo>
  <gazebo reference="front_left_wheel">
    <mu1 value="1.0"/>
    <mu2 value="1.0"/>
    <kp value="10000000.0" />
    <kd value="1.0" />
    <fdir1 value="1 0 0"/>
  </gazebo>

  <gazebo reference="front_right_wheel">
  <mu1 value="1.0"/>
  <mu2 value="1.0"/>
  <kp value="10000000.0" />
  <kd value="1.0" />
  <fdir1 value="1 0 0"/>
  </gazebo>

  <gazebo reference="rear_left_wheel">
    <mu1 value="1.0"/>
    <mu2 value="1.0"/>
    <kp value="10000000.0" />
    <kd value="1.0" />
    <fdir1 value="1 0 0"/>
  </gazebo>

  <gazebo reference="rear_left_wheel">
    <mu1 value="1.0"/>
    <mu2 value="1.0"/>
    <kp value="10000000.0" />
    <kd value="1.0" />
    <fdir1 value="1 0 0"/>
  </gazebo>
  <!--######################################################################-->

  <gazebo>
    <plugin filename="libhector_gazebo_ros_imu.so"
              name="hector_imu_plugin" >
      <alwaysOn>true</alwaysOn>
      <bodyName>imu_link</bodyName>
      <topicName>imu</topicName>
      <serviceName>/imu/calibrate</serviceName>
      <gaussianNoise>0.0</gaussianNoise>
      <updateRate>50.0</updateRate>
      <frameName>imu_link</frameName>
      <accelOffset>0 0 0 </accelOffset>
      <accelGaussianNoise>0 0 0</accelGaussianNoise>
      <accelDrift>0 0 0 </accelDrift>
      <accelDriftFrequency>0 0 0</accelDriftFrequency>
      <rateOffset>0 0 0</rateOffset>
      <rateGaussianNoise> 0 0 0</rateGaussianNoise>
      <rateDrift>0 0 0 </rateDrift>
      <rateDriftFrequency> 0 0 0</rateDriftFrequency>
      <yawOffset> 0 </yawOffset>
      <yawGaussianNoise> 0 </yawGaussianNoise>
      <yawDrift> 0 </yawDrift>
      <yawDriftFrequency> 0 </yawDriftFrequency> 
    </plugin>
  </gazebo>

<!--######################################################################-->
  <gazebo>
    <plugin name="gps_controller" filename="libhector_gazebo_ros_gps.so">
        <robotNamespace>/</robotNamespace>
        <updateRate>40</updateRate>
        <bodyName>chassis</bodyName>
        <frameId>chassis</frameId>
        <topicName>navsat/fix</topicName>
        <velocityTopicName>navsat/vel</velocityTopicName>
        <referenceLatitude>50.0</referenceLatitude>
        <referenceLongitude>60.0</referenceLongitude>
        <referenceHeading>0</referenceHeading>
        <referenceAltitude>0</referenceAltitude>
        <drift>0.0001 0.0001 0.0001</drift>
    </plugin>
  </gazebo>
<!--######################################################################-->

<gazebo reference="lidar_link">
    <sensor type="gpu_ray" name="os1_lidar">
      <pose>0 0 0 0 0 0</pose>
          <visualize>false</visualize>
          <update_rate>10</update_rate>
          <ray>
            <scan>
              <horizontal>
                <samples>512</samples>
                <resolution>1</resolution>
                <min_angle>-3.141529</min_angle>
                <max_angle>3.141529</max_angle>
              </horizontal>
              <vertical>
                <samples>64</samples>
                <resolution>1</resolution>
                <min_angle>-3.141529</min_angle>
                <max_angle>-3.141529</max_angle>
              </vertical>
            </scan>
            <range>
              <min>0.9</min>
              <max>75.0</max>
              <resolution>0.03</resolution>
            </range>
          </ray>
      <plugin name="gazebo_ros_head_hokuyo_controller" filename="libgazebo_ros_gpu_laser.so">
        <topicName>/rrbot/laser/scan</topicName>
        <frameName>hokuyo_link</frameName>
      </plugin>
    </sensor>
</gazebo>

<!--######################################################################-->

  <transmission name="front_left_wheel_trans" type="SimpleTransmission">
    <type>transmission_interface/SimpleTransmission</type>
    <actuator name="front_left_wheel_motor">
    <hardwareInterface>hardware_interface/VelocityJointInterface</hardwareInterface>
    <mechanicalReduction>1</mechanicalReduction>
    </actuator>
    <joint name="front_left_wheel_joint">
    <hardwareInterface>hardware_interface/VelocityJointInterface</hardwareInterface>
    </joint>
  </transmission>

  <transmission name="middle_left_wheel_trans" type="SimpleTransmission">
    <type>transmission_interface/SimpleTransmission</type>
    <actuator name="middle_left_wheel_motor">
    <hardwareInterface>hardware_interface/VelocityJointInterface</hardwareInterface>
    <mechanicalReduction>1</mechanicalReduction>
    </actuator>
    <joint name="middle_left_wheel_joint">
    <hardwareInterface>hardware_interface/VelocityJointInterface</hardwareInterface>
    </joint>
  </transmission>

  <transmission name="middle_right_wheel_trans" type="SimpleTransmission">
    <type>transmission_interface/SimpleTransmission</type>
    <actuator name="middle_right_wheel_motor">
    <hardwareInterface>hardware_interface/VelocityJointInterface</hardwareInterface>
    <mechanicalReduction>1</mechanicalReduction>
    </actuator>
    <joint name="middle_right_wheel_joint">
    <hardwareInterface>hardware_interface/VelocityJointInterface</hardwareInterface>
    </joint>
  </transmission>

  <transmission name="front_right_wheel_trans" type="SimpleTransmission">
    <type>transmission_interface/SimpleTransmission</type>
    <actuator name="front_right_wheel_motor">
    <hardwareInterface>hardware_interface/VelocityJointInterface</hardwareInterface>
    <mechanicalReduction>1</mechanicalReduction>
    </actuator>
    <joint name="front_right_wheel_joint">
    <hardwareInterface>hardware_interface/VelocityJointInterface</hardwareInterface>
    </joint>
  </transmission>

  <transmission name="rear_left_wheel_trans" type="SimpleTransmission">
    <type>transmission_interface/SimpleTransmission</type>
    <actuator name="rear_left_wheel_motor">
    <hardwareInterface>hardware_interface/VelocityJointInterface</hardwareInterface>
    <mechanicalReduction>1</mechanicalReduction>
    </actuator>
    <joint name="rear_left_wheel_joint">
    <hardwareInterface>hardware_interface/VelocityJointInterface</hardwareInterface>
    </joint>
  </transmission>

  <transmission name="rear_right_wheel_trans" type="SimpleTransmission">
    <type>transmission_interface/SimpleTransmission</type>
    <actuator name="rear_right_wheel_motor">
    <hardwareInterface>hardware_interface/VelocityJointInterface</hardwareInterface>
    <mechanicalReduction>1</mechanicalReduction>
    </actuator>
    <joint name="rear_right_wheel_joint">
      <hardwareInterface>hardware_interface/VelocityJointInterface</hardwareInterface>
    </joint>
  </transmission>
</robot>
